<?xml version="1.0" ?>
<robot name="motor" xmlns:xacro="http://www.ros.org/wiki/xacro">

  <!--==================== TODO ===========================================-->
  <!-- Delete virtual joint 4 -->

  <!--==================== Model Description ==============================-->


  <!--==================== Color Table ====================================-->

  <material name="white">
    <color rgba="1.0 1.0 1.0 1"/>
  </material>

  <material name="silver">
    <color rgba="0.75 0.75 0.75 1"/>
  </material>

  <material name="gray">
    <color rgba="0.5 0.5 0.5 1"/>
  </material>

  <material name="black">
    <color rgba="0.0 0.0 0.0 1"/>
  </material>

  <material name="maroon">
    <color rgba="0.5 0.0 0.0 1"/>
  </material>

  <material name="red">
    <color rgba="1.0 0.0 0.0 1"/>
  </material>

  <material name="orange">
    <color rgba="1.0 0.65 0.0 1"/>
  </material>

  <material name="yellow">
    <color rgba="1.0 1.0 0.0 1"/>
  </material>

  <material name="olive">
    <color rgba="0.5 0.5 0.0 1"/>
  </material>

  <material name="lime">
    <color rgba="0.0 1.0 0.0 1"/>
  </material>

  <material name="green">
    <color rgba="0.0 0.5 0.0 1"/>
  </material>

  <material name="aqua">
    <color rgba="0.0 1.0 1.0 1"/>
  </material>

  <material name="aqua">
    <color rgba="0.0 1.0 1.0 1"/>
  </material>

  <material name="blue">
    <color rgba="0.0 0.0 1.0 1"/>
  </material>

  <material name="navy">
    <color rgba="0.0 0.0 0.5 1"/>
  </material>

  <material name="teal">
    <color rgba="0.0 0.5 0.5 1"/>
  </material>

  <material name="fuchsia">
    <color rgba="1.0 0.0 1.0 1"/>
  </material>

  <material name="purple">
    <color rgba="0.5 0.0 0.5 1"/>
  </material>

  <!--==================== Physical Links =================================-->

  <link name="linkBase">

    <inertial>
      <origin xyz="0.0 0.0 0.15" rpy="0 0 0" />
      <mass value="0.2" />
      <inertia
        ixx="0.01"
        ixy="0.0"
        ixz="0.0"
        iyy="0.01"
        iyz="0.0"
        izz="0.03" />
    </inertial>

    <visual>
      <origin xyz="0.0 0.0 0.15" rpy="0 0 0" />
      <geometry>
        <box size="0.1 0.1 0.3" />
      </geometry>
      <material name="purple"/>
    </visual>

    <collision>
      <origin xyz="0.0 0.0 0.15" rpy="0 0 0" />
      <geometry>
        <box size="0.1 0.1 0.3" />
      </geometry>
    </collision>

  </link>


  <link name="linkAxis">

    <inertial>
      <origin xyz="0.0 0.0 0.15" rpy="0 0 0" />
      <mass value="0.1" />
      <inertia
        ixx="0.01e-5"
        ixy="0.0"
        ixz="0.0"
        iyy="0.5e-5"
        iyz="0.0"
        izz="0.1e-5" />
    </inertial>
    
    <visual>
      <origin xyz="0.0 0.0 0.15" rpy="0 0 0" />
      <geometry>
        <cylinder radius="0.03" length="0.3"/>
      </geometry>
      <material name="black"/>
    </visual>

    <collision>
      <origin xyz="0.0 0.0 0.15" rpy="0 0 0" />
      <geometry>
        <cylinder radius="0.03" length="0.3"/>
      </geometry>
    </collision>

  </link>


  <link name="linkWing">

    <inertial>
      <origin xyz="0.0 0.0 0.0" rpy="0 0 0" />
      <mass value="0.001" />
      <inertia
        ixx="0.1e-10"
        ixy="0.0"
        ixz="0.0"
        iyy="0.1e-10"
        iyz="0.0"
        izz="0.1e-10" />
    </inertial>
    
    <visual>
      <origin xyz="0 0 0.005" rpy="0 0 0" />
      <geometry>
        <box size="0.4 0.01 0.01" />
      </geometry>
      <material name="navy"/>
    </visual>

    <collision>
      <origin xyz="0 0 0" rpy="0 0 0" />
      <geometry>
        <box size="0.4 0.01 0.01" />
      </geometry>
    </collision>

  </link>


  <!--==================== Active Joints ==================================-->

  <joint name="jointActive1" type="continuous">

    <origin xyz="0.0 0.0 0.1" rpy="0 0 0" />
    <parent link="linkBase" />
    <child link="linkAxis" />
    <axis xyz="0 0 1" />
    <limit effort="500" velocity="500"/>
    <joint_properties damping=".0" friction=".0"/>
  </joint>



  <joint name="jointFixed" type="fixed">

    <origin xyz="0.0 0.0 0.3" rpy="0 0 0" />
    <parent link="linkAxis" />
    <child link="linkWing" />
    <axis xyz="0 0 1" />

  </joint>

</robot>
